Workbook
Name BrowseRecords: RiskSerializationData8!$6:$10
Name SerializationHeader: RiskSerializationData8!$A$1:$B$3

Sheet RiskSerializationData8
A1: Written By Version | B1: 8.9.0
A2: Serialization Major Version | B2: 4
A3: Serialization Minor Version | B3: 0
A5: Browse Record | B5: Display Mode | C5: Sens Graph Type | D5: Cond Sens Settings | E5: Scenario Settings | F5: Selected Scenario | J5: Distribution Options | K5: Distribution GS | L5: Distribution Curves | N5: Sens Tornado Options | O5: Sens Tornado GS | P5: Sens Tornado Curves | R5: Scen Tornado Options | S5: Scen Tornado GS | T5: Scen Tornado Curves | V5: Sens Spider Option | W5: Sens Spider GS | X5: Sens Spider Curves
A6: =ModelRef('SW23'!$C$274,2,0,0) -> #NAME? | B6: 0 | C6: 3 | F6: 0 | J6: TRUE | K6: GF1_rK0qDwEAEwBHAQwjACcANgCGAJoAmwCyAMAAIQFDAT0BKwD//wAAAAAAAAEEAAAAAAEwAAAAAQtEaWV0IDEgRmVlZAE/Q29tcGFyaXNvbiB3aXRoIFJpc2tOb3JtYWwoMTkwLDc0Ljg3OSxSaXNrVHJ1bmNhdGVQKDAuMDUsMC45NSkpAQEQAAIAAQpTdGF0aXN0aWNzAwEBAP8BAQEBAQluZy9rZyBkcnkBAQEABAAAAAEBAQEBAAEBAQAEAAAAAscAAuMAABgAC0RpZXQgMSBGZWVkAAAA/wAA/wEAAAIAAgA8AC9SaXNrTm9ybWFsKDE5MCw3NC44NzksUmlza1RydW5jYXRlUCgwLjA1LDAuOTUpKQABAP8AAAABAAACACkBMwEBAQMBmpmZmZmZqT8AAGZmZmZmZu4/AAAFAAEBAQABAQEA | L6: =ModelRef('SW23'!$C$274,2,0,0)+ModelRef('SW23'!$C$274,3,0,-1) -> #NAME?
A7: =ModelRef('SW14'!$C$542,2,0,0) -> #NAME? | B7: 0 | C7: 3 | F7: 0 | J7: TRUE | K7: GF1_rK0qDwEAEwBJAQwjACcANgCHAJsAnACzAMEAIwFFAT8BKwD//wAAAAAAAAEEAAAAAAEwAAAAAQtEaWV0IDcgRmVlZAFAQ29tcGFyaXNvbiB3aXRoIFJpc2tOb3JtYWwoMTMwMCw1MTIuMzMsUmlza1RydW5jYXRlUCgwLjA1LDAuOTUpKQEBEAACAAEKU3RhdGlzdGljcwMBAQD/AQEBAQEJbmcva2cgZHJ5AQEBAAQAAAABAQEBAQABAQEABAAAAALIAALkAAAYAAtEaWV0IDcgRmVlZAAAAP8AAP8BAAACAAIAPQAwUmlza05vcm1hbCgxMzAwLDUxMi4zMyxSaXNrVHJ1bmNhdGVQKDAuMDUsMC45NSkpAAEA/wAAAAEAAAIAKwE1AQEBAwGamZmZmZmpPwAAZmZmZmZm7j8AAAUAAQEBAAEBAQA= | L7: =ModelRef('SW14'!$C$542,2,0,0)+ModelRef('SW14'!$C$542,3,0,-1) -> #NAME?
A8: =ModelRef('SW10'!$B$3,2,0,0) -> #NAME? | B8: 0 | C8: 3 | F8: 0 | J8: TRUE | K8: GF1_rK0qDwEAEwBFAQwjACcAOQCKAJ4AnwCvAL0AHwFBATsBKwD//wAAAAAAAAEEAAAAAAQwLjAwAAAAAQxCaXJ0aCBXZWlnaHQBP0NvbXBhcmlzb24gd2l0aCBSaXNrTm9ybWFsKDM1LjQ1LDMuMjcsUmlza1RydW5jYXRlUCgwLjA1LDAuOTUpKQEBEAACAAEKU3RhdGlzdGljcwMBAQD/AQEBAQECa2cBAQEABAAAAAEBAQEBAAEBAQAEAAAAAsQAAuEAABkADEJpcnRoIFdlaWdodAAAAP8AAP8BAAACAAIAPAAvUmlza05vcm1hbCgzNS40NSwzLjI3LFJpc2tUcnVuY2F0ZVAoMC4wNSwwLjk1KSkAAQD/AAAAAQAAAgAnATEBAQEDAZqZmZmZmak/AABmZmZmZmbuPwAABQABAQEAAQEBAA== | L8: =ModelRef('SW10'!$B$3,2,0,0)+ModelRef('SW10'!$B$3,3,0,-1) -> #NAME?
A9: =ModelRef('SW10'!$V$678,2,0,0) -> #NAME? | B9: 0 | C9: 3 | F9: 0 | J9: TRUE | K9: GF1_rK0qDwEAEwBMAQwjACcAOgCPAKMApACyAMAAJgFIAUIBKwD//wAAAAAAAAEEAAAAAAUwLjAwMAAAAAEQUEZBUyBNVVNDTEUgRlJBQwE/Q29tcGFyaXNvbiB3aXRoIFJpc2tOb3JtYWwoMC4yMzEsMC4wOSxSaXNrVHJ1bmNhdGVQKDAuMDUsMC45NSkpAQEQAAIAAQpTdGF0aXN0aWNzAwEBAP8BAQEBAQABAQEABAAAAAEBAQEBAAEBAQAEAAAAAscAAugAAB0AEFBGQVMgTVVTQ0xFIEZSQUMAAAD/AAD/AQAAAgACADwAL1Jpc2tOb3JtYWwoMC4yMzEsMC4wOSxSaXNrVHJ1bmNhdGVQKDAuMDUsMC45NSkpAAEA/wAAAAEAAAIALgE4AQEBAwGamZmZmZmpPwAAZmZmZmZm7j8AAAUAAQEBAAEBAQA= | L9: =ModelRef('SW10'!$V$678,2,0,0)+ModelRef('SW10'!$V$678,3,0,-1) -> #NAME?
A10: =ModelRef('SW10'!$H$35,2,0,0) -> #NAME? | B10: 0 | C10: 3 | F10: 0 | J10: TRUE | K10: GF1_rK0qDwEAEwBMAQwjACcAOQCOAKIAowCyAMAAJgFIAUIBKwD//wAAAAAAAAEEAAAAAAQwLjAwAAAAARBXYXRlciBJbnRha2UgQ293AT9Db21wYXJpc29uIHdpdGggUmlza05vcm1hbCg1Ni40Nyw4LjE2LFJpc2tUcnVuY2F0ZVAoMC4wNSwwLjk1KSkBARAAAgABClN0YXRpc3RpY3MDAQEA/wEBAQEBAUwBAQEABAAAAAEBAQEBAAEBAQAEAAAAAscAAugAAB0AEFdhdGVyIEludGFrZSBDb3cAAAD/AAD/AQAAAgACADwAL1Jpc2tOb3JtYWwoNTYuNDcsOC4xNixSaXNrVHJ1bmNhdGVQKDAuMDUsMC45NSkpAAEA/wAAAAEAAAIALgE4AQEBAwGamZmZmZmpPwAAZmZmZmZm7j8AAAUAAQEBAAEBAQA= | L10: =ModelRef('SW10'!$H$35,2,0,0)+ModelRef('SW10'!$H$35,3,0,-1) -> #NAME?

Sheet SW0
A1: SW | B1: Contents
A2: 1 | B2: Data on tissue half-life and exposure calculations
A3: =A2+1 -> 2 | B3: Data on PFOS concentrations and mass fractions in different tissues
A4: =A3+1 -> 3 | B4: Data on dry matter intake (DMI) and milk production for dairy cows
A5: =A4+1 -> 4 | B5: Forage intake calculations for calves
A6: =A5+1 -> 5 | B6: Combined forage intake data for calves
A7: =A6+1 -> 6 | B7: Water intake data for cows and finishers at different temperatures
A8: =A7+1 -> 7 | B8: Various parameter values and equations for the PFOS model
A9: =A8+1 -> 8 | B9: Deterministic model for Case Study 1
A10: =A9+1 -> 9 | B10: Graph of model versus in vivo results for Case Study 1
A11: =A10+1 -> 10 | B11: Probabilistic model for Case Study 1
A12: =A11+1 -> 11 | B12: Statistical analysis of results for muscle PFOS at 675 days
A13: =A12+1 -> 12 | B13: Deterministic model for Case Study 2
A14: =A13+1 -> 13 | B14: Graph of model versus in vivo results for Case Study 2
... A25: =A24+1 -> 24 | B25: Statistical analysis results for muscle PFOS at 540 days in the generic model

Sheet SW1
A1: 129.91777 | C1: =AVERAGE(A1:A4200) -> 108.86449 | E1: Study | F1: Tissue | G1: Half Life | H1: S.D. | I1: Exposure | J1: Type | K1: Tissue | L1: Duration | M1: Divisor | N1: Total Weight
A2: 124.85987 | C2: =_xlfn.STDEV.P(A1:A4200) -> 40.484373 | E2: Lupton 2014 | F2: Body | G2: 114.2 | H2: =G2*0.2 -> 22.84 | I2: 1 | J2: 3 | K2: 3 | L2: 1 | M2: 1 | N2: =I2*J2*K2*L2/M2 -> 9 | O2: =G2*N2 -> 1027.8
A3: 119.31015 | E3: Lupton 2015 | F3: Steer Plasma | G3: 120 | H3: 4.1 | I3: 1 | J3: 3 | K3: 1 | L3: 3 | M3: 3 | N3: =I3*J3*K3*L3/M3 -> 3 | O3: =G3*N3 -> 360
A4: 104.88912 | E4: Lupton 2015 | F4: Hiefer Plasma | G4: 106 | H4: 23.1 | I4: 1 | J4: 3 | K4: 1 | L4: 3 | M4: 3 | N4: =I4*J4*K4*L4/M4 -> 3 | O4: =G4*N4 -> 318
A5: 109.14386 | E5: Lupton 2015 | F5: Grouped Muscle | G5: 165 | H5: =G5*0.2 -> 33 | I5: 1 | J5: 3 | K5: 3 | L5: 3 | M5: 3 | N5: =I5*J5*K5*L5/M5 -> 9 | O5: =G5*N5 -> 1485
A6: 130.66413 | E6: Drew 2021 | F6: Serum | G6: 74.1 | H6: 13.4 | I6: 3 | J6: 1 | K6: 1 | L6: 3 | M6: 2 | N6: =I6*J6*K6*L6/M6 -> 4.5 | O6: =G6*N6 -> 333.45
A7: 75.011292 | E7: Drew 2021 | F7: Muscle | G7: 77 | H7: =G7*0.2 -> 15.4 | I7: 3 | J7: 1 | K7: 3 | L7: 3 | M7: 2 | N7: =I7*J7*K7*L7/M7 -> 13.5 | O7: =G7*N7 -> 1039.5
A8: 108.74896 | N8: =SUM(N2:N7) -> 42 | O8: =SUM(O2:O7) -> 4563.75 | P8: =O8/N8 -> 108.66071
A9: 126.67727
A10: 121.35497
A11: 113.02342
A12: 121.82536
A13: 74.880862
A14: 113.57792
A15: 114.85352
A16: 76.76864
A17: 139.45082
A18: 81.954406
A19: 113.85233
A20: 114.96174
... A4200: 115.43436

Sheet SW2
A1: Mass of Tissues | B1: % BW | C1: Fraction | D1: SD
A2: Blood | B2: 3.99 | C2: =B2/100 -> 0.0399 | D2: 0.0068
A3: Liver | B3: 1.22 | C3: =B3/100 -> 0.0122 | D3: 0.0018
A4: Kidney | B4: 0.21 | C4: =B4/100 -> 0.0021 | D4: 0.005
A5: Muscle | B5: 36.1 | C5: =B5/100 -> 0.361 | D5: 0.1173
A6: Fat | B6: 12.18 | C6: =B6/100 -> 0.1218 | D6: 0.0506
A7: Bone | B7: 8.66 | C7: =B7/100 -> 0.0866 | D7: 0.0149
A9: PFOS Conc in Tissues | B9: Drew | C9: Lupton Steer | D9: Lupton Heifer 343
A10: Conc in Blood | B10: 1 | C10: 0.15 | D10: 8.33
A11: Conc in Liver | B11: 1.64 | C11: 0.149 | D11: 4.74
A12: Conc in Kidney | B12: 0.58 | C12: 0.082 | D12: 2.36
A13: Conc in Muscle | B13: 0.08 | C13: =AVERAGE(0.004,0.007,0.004,0.004) -> 0.00475 | D13: =AVERAGE(0.27,0.3,0.17,0.39) -> 0.2825
A14: Conc in Fat | C14: 0.037 | D14: 0.87
A15: Conc in Bone | C15: 0.003 | D15: 0.23
A17: PFOS Mass in Tissues
A18: Mass in Blood | B18: =B10*$B2 -> 3.99 | C18: =C10*$B2 -> 0.5985 | D18: =D10*$B2 -> 33.2367
A19: Mass in Liver | B19: =B11*$B3 -> 2.0008 | C19: =C11*$B3 -> 0.18178 | D19: =D11*$B3 -> 5.7828
A20: Mass in Kidney | B20: =B12*$B4 -> 0.1218 | C20: =C12*$B4 -> 0.01722 | D20: =D12*$B4 -> 0.4956
A21: Mass in Muscle | B21: =B13*$B5 -> 2.888 | C21: =C13*$B5 -> 0.171475 | D21: =D13*$B5 -> 10.19825
A22: Mass in Fat | C22: =C14*$B6 -> 0.45066 | D22: =D14*$B6 -> 10.5966
A23: Mass in Bone | C23: =C15*$B7 -> 0.02598 | D23: =D15*$B7 -> 1.9918
A25: Total mass of PFOS in Tissues | B25: =SUM(B18:B21) -> 9.0006 | C25: =SUM(C18:C23) -> 1.445615 | D25: =SUM(D18:D23) -> 62.30175
A26: Mass Fraction PFOS in Muscle | B26: =(B21)/B25 -> 0.3208675 | C26: =(C21)/C25 -> 0.11861734 | D26: =(D21)/D25 -> 0.16369123
A27: Muscle:Serum Partition | B27: =B13/B10 -> 0.08
B29: muscle:body
A30: Drew | B30: 0.321
A31: Lupton Average | B31: =(0.119+0.164)/2 -> 0.1415
A32: Average | B32: =AVERAGE(B30:B31) -> 0.23125
A33: St Dev | B33: =_xlfn.STDEV.P(B30:B31) -> 0.08975

Sheet SW3
B2: Days Since Calving | C2: DMI per Level of Nutrition (kg/d) | F2: Average DMI (kg) | G2: DMI SD
C3: A | D3: B | E3: C
B4: 30 | C4: 11.14 | D4: 11.96 | E4: 13.6 | F4: =AVERAGE(C4:E4) -> 12.233333 | G4: =_xlfn.STDEV.P(C4:E4) -> 1.0227197
B5: 60 | C5: 11.4 | D5: 12.23 | E5: 13.42 | F5: =AVERAGE(C5:E5) -> 12.35 | G5: =_xlfn.STDEV.P(C5:E5) -> 0.82901548
B6: 90 | C6: 12.12 | D6: 12.72 | E6: 13.79 | F6: =AVERAGE(C6:E6) -> 12.876667 | G6: =_xlfn.STDEV.P(C6:E6) -> 0.69071621
B7: 120 | C7: 11.83 | D7: 12.43 | E7: 13.5 | F7: =AVERAGE(C7:E7) -> 12.586667 | G7: =_xlfn.STDEV.P(C7:E7) -> 0.69071621
B8: 150 | C8: 11.54 | D8: 12.14 | E8: 13.21 | F8: =AVERAGE(C8:E8) -> 12.296667 | G8: =_xlfn.STDEV.P(C8:E8) -> 0.69071621
B9: 180 | C9: 11.3 | D9: 11.9 | E9: 12.97 | F9: =AVERAGE(C9:E9) -> 12.056667 | G9: =_xlfn.STDEV.P(C9:E9) -> 0.69071621
B10: 210 | C10: 10.68 | D10: 11.28 | E10: 12.35 | F10: =AVERAGE(C10:E10) -> 11.436667 | G10: =_xlfn.STDEV.P(C10:E10) -> 0.69071621
B13: Days Since Calving | C13: Peak Milk Production (kg/d) | G13: Average Milk Production (kg/d) | H13: Milk SD
C14: 5 | D14: 8 | E14: 11 | F14: 14
B15: 30 | C15: 3.9999973 | D15: 6.4275445 | E15: 8.8146 | F15: 11.2 | G15: 7.6105354 | H15: 2.6818595
B16: 60 | C16: 5.0329961 | D16: 8.0459092 | E16: 11.007172 | F16: 14.054519 | G16: 9.5351492 | H16: 3.3570364
B17: 90 | C17: 4.7747464 | D17: 7.5294098 | E17: 10.335723 | F17: 13.193687 | G17: 8.9583915 | H17: 3.1376601
B18: 120 | C18: 3.9483473 | D18: 6.3242446 | E18: 8.6312752 | F18: 10.955523 | G18: 7.4648474 | H18: 2.6082616
B19: 150 | C19: 3.0702984 | D19: 4.9296962 | E19: 6.8235273 | F19: 8.6484919 | G19: 5.8680034 | H19: 2.0827696
B20: 180 | C20: 2.3299825 | D20: 3.6900976 | E20: 5.1190793 | F20: 6.4619777 | G20: 4.4002843 | H20: 1.5457814
B21: 210 | C21: 1.7273999 | D21: 2.7087488 | E21: 3.672881 | F21: 4.6714465 | G21: 3.195119 | H21: 1.0952802

Sheet SW4
M6: Forage Source | N6: DEF | O6: Forage Source | P6: DEF
A7: Age (d) | B7: BW (kg) | C7: DMIF (kg) | D7: DMIF SD | E7: DMIM (kg) | F7: DMIM SD (kg) | G7: DMIF+M | M7: Alfalfa Hay | N7: 2.43 | O7: Mix Grass+Leg. Sil., immature | P7: 2.39
A8: 0 | B8: 35.451613 | C8: =G8-(4.87*E9)/P$31 -> -0.90115103 | D8: =C8*P$32 -> -0.23699936 | G8: =(0.0783*B8)/P$31 -> 1.2247888 | M8: Almond Hulls | N8: 2.89 | O8: Mix Grass+Leg. Sil., mature | P8: 2.07
A9: 30 | B9: 53.769011 | C9: =G9-(4.87*E10)/P$31 -> -0.80594307 | D9: =C9*P$32 -> -0.21196003 | E9: ='SW3'!$G$15*0.13 -> 0.98936961 | F9: ='SW3'!H15*0.13 -> 0.34864173 | G9: =(0.0783*B9)/P$31 -> 1.8576216 | M9: Barley Silage, headed | N9: 2.28 | O9: Mix Grass+Leg. Sil., mid-mat. | P9: 2.25
A10: 60 | B10: 75.036966 | C10: =G10-(4.87*E11)/P$31 -> 0.089938574 | D10: =C10*P$32 -> 0.02365351 | E10: ='SW3'!G16*0.13 -> 1.2395694 | F10: ='SW3'!H16*0.13 -> 0.43641473 | G10: =(0.0783*B10)/P$31 -> 2.5923908 | M10: Bermudagrass hay, Coastal | N10: 1.87 | O10: Mix Grass+Legume Hay, mature | P10: 2.11
A11: 90 | B11: 98.965699 | C11: =G11-(4.87*E12)/P$31 -> 1.3338419 | D11: =C11*P$32 -> 0.35079546 | E11: ='SW3'!G17*0.13 -> 1.1645909 | F11: ='SW3'!H17*0.13 -> 0.40789581 | G11: =(0.0783*B11)/P$31 -> 3.419085 | M11: Bermudagrass hay, Tifton-85 | N11: 1.86 | O11: Mix Grass+Legume Hay, immat. | P11: 2.46
A12: 120 | B12: 125.23954 | C12: =G12-(4.87*E13)/P$31 -> 2.6876204 | D12: =C12*P$32 -> 0.70683414 | E12: ='SW3'!G18*0.13 -> 0.97043016 | F12: ='SW3'!H18*0.13 -> 0.33907401 | G12: =(0.0783*B12)/P$31 -> 4.3267983 | M12: Corn Silage, immature | N12: 2.45 | O12: Mostly Grass Hay, immature | P12: 2.35
A13: 150 | B13: 153.51691 | C13: =G13-(4.87*E14)/P$31 -> 4.0745474 | D13: =C13*P$32 -> 1.0715908 | E13: ='SW3'!G19*0.13 -> 0.76284045 | F13: ='SW3'!H19*0.13 -> 0.27076004 | G13: =(0.0783*B13)/P$31 -> 5.3037303 | M13: Corn Silage, mature | N13: 2.78 | O13: Mostly Grass Hay, mature | P13: 2.08
A14: 180 | B14: 183.43036 | C14: =G14-(4.87*E15)/P$31 -> 5.4446557 | D14: =C14*P$32 -> 1.4319242 | E14: ='SW3'!G20*0.13 -> 0.57203696 | F14: ='SW3'!H20*0.13 -> 0.20095158 | G14: =(0.0783*B14)/P$31 -> 6.3371856 | M14: Corn Silage, normal | N14: 2.75 | O14: Mostly Grass Hay, mid-mat. | P14: 2.19
A15: 210 | B15: 214.58654 | C15: =G15-(4.87*E16)/P$31 -> 7.4135748 | D15: =C15*P$32 -> 1.9497425 | E15: ='SW3'!G21*0.13 -> 0.41536548 | F15: ='SW3'!H21*0.13 -> 0.14238642 | G15: =(0.0783*B15)/P$31 -> 7.4135748 | M15: Corn, Yellow, cobs | N15: 1.76 | O15: Mostly Grass Silage, mid-mat. | P15: 2.19
A16: 240 | B16: 246.56618 | C16: =G16-(4.87*E17)/P$31 -> 8.5184133 | D16: =C16*P$32 -> 2.240311 | G16: =(0.0783*B16)/P$31 -> 8.5184133 | M16: Cottonseed, hulls | N16: 1.69 | O16: Mostly Grass Silage, immat. | P16: 2.34
B17: DMIF = (0.0783 x BW - 4.87 x DMIM)/DEF calculated from fluid milk production | M17: Cottonseed, whole with lint | N17: 2.89 | O17: Mostly Grass Silage, mature | P17: 2.01
B18: DMIF: dry matter intake for forage | M18: Grass Hay, cool season, mature | N18: 2.04 | O18: Mostly Legume Hay, immature | P18: 2.49
B19: DMIM: dry matter intake for milk | M19: Grass Hay, cool season, immature | N19: 2.36 | O19: Mostly Legume Hay, mature | P19: 2.2
B20: DMIF+M: total dry matter intake for forage plus milk | M20: Grass Hay, cool season, mid-mat. | N20: 2.18 | O20: Mostly Legume Hay, mid-mat. | P20: 2.35
B21: Milk: assume 13% DM | M21: Grass Pasture, cool season, veg. | N21: 2.39 | O21: Mostly Legume Silage, immature | P21: 2.38
B22: DEF: digestible energy in Mcal/kg of forage =2.27 (average for 50 forages) | M22: Grass Silage, cool season, immature | N22: 2.3 | O22: Mostly Legume Silage, mid-mat. | P22: 2.27
M23: Grass Silage, cool season, mature | N23: 1.98 | O23: Mostly Legume Silage, mature | P23: 2.11
M24: Grass Silage, cool season, mid-mat. | N24: 2.16 | O24: Oats, Hay, headed | P24: 2.16
M25: Legume Forage Hay, immature | N25: 2.62 | O25: Oats, Silage, headed | P25: 2.04
M26: Legume Forage Hay, mature | N26: 2.21 | O26: Rye, Annual, Silage, veg. | P26: 2.12
M27: Legume Forage Hay, mid-mat. | N27: 2.43 | O27: Sorghum, Grain Type, Silage | P27: 2.17
M28: Legume Forage Pasture, veg. | N28: 2.71 | O28: Sorghum, Sudan Type, Hay | P28: 2
M29: Legume Forage Silage, mid-mat. | N29: 2.35 | O29: Sorghum, Sudan Type, Silage | P29: 1.95
M30: Legume Forage Silage, immat. | N30: 2.52 | O30: Soybean, hulls | P30: 2.25
M31: Legume Forage Silage, mature | N31: 2.19 | O31: Average | P31: =AVERAGE(N7:N32,P7:P30) -> 2.2664
M32: Mix Grass+Leg. Hay, mid-mat. | N32: 2.3 | O32: SD | P32: =_xlfn.STDEV.P(N7:N32,P7:P30) -> 0.26299627

Sheet SW5
B3: Age (d) | C3: BW (kg) | D3: Original Data | F3: Extrapoalted Data | H3: Combined Data
D4: Forage DMI (kg) | E4: SD | F4: Forage DMI (kg) | G4: SD | H4: Forage DMI (kg) | I4: SD
B5: 60 | C5: 75.036966 | D5: ='SW4'!C10 -> 0.089938574 | E5: ='SW4'!D10 -> 0.02365351 | H5: =D5 -> 0.089938574 | I5: =E5 -> 0.02365351
B6: 90 | C6: 98.965699 | D6: ='SW4'!C11 -> 1.3338419 | E6: ='SW4'!D11 -> 0.35079546 | H6: =D6 -> 1.3338419 | I6: =E6 -> 0.35079546
B7: 120 | C7: 125.23954 | D7: ='SW4'!C12 -> 2.6876204 | E7: ='SW4'!D12 -> 0.70683414 | H7: =D7 -> 2.6876204 | I7: =E7 -> 0.70683414
B8: 150 | C8: 153.51691 | D8: ='SW4'!C13 -> 4.0745474 | E8: ='SW4'!D13 -> 1.0715908 | H8: =D8 -> 4.0745474 | I8: =E8 -> 1.0715908
B9: 180 | C9: 183.43036 | D9: ='SW4'!C14 -> 5.4446557 | E9: ='SW4'!D14 -> 1.4319242 | F9: =(0.0186*B9) + 2.5417 -> 5.8897 | G9: 0.44988888 | H9: =(D9+F9)/2 -> 5.6671779 | I9: =(E9+G9)/2 -> 0.94090652
B10: 210 | C10: 214.58654 | D10: ='SW4'!C15 -> 7.4135748 | E10: ='SW4'!D15 -> 1.9497425 | F10: =(0.0186*B10) + 2.5417 -> 6.4477 | G10: 0.44988888 | H10: =(D10+F10)/2 -> 6.9306374 | I10: =(E10+G10)/2 -> 1.1998157
B11: 240 | C11: 246.56618 | D11: ='SW4'!C16 -> 8.5184133 | E11: ='SW4'!D16 -> 2.240311 | F11: =(0.0186*B11) + 2.5417 -> 7.0057 | G11: 0.44988888 | H11: =(D11+F11)/2 -> 7.7620567 | I11: =(E11+G11)/2 -> 1.3450999 | M11: BW (kg) | N11: DMI per Level of Nutriion (kg/d) | S11: Average | T11: SD
B12: 270 | C12: 279 | F12: =(0.0186*B12) + 2.5417 -> 7.5637 | G12: 0.44988888 | H12: =F12 -> 7.5637 | I12: =G12 -> 0.44988888 | N12: A | O12: B | P12: C | Q12: D | R12: E
B13: 290 | C13: 300 | D13: =S13 -> 7.86 | E13: =T13 -> 0.44988888 | H13: =S13 -> 7.86 | I13: =T13 -> 0.44988888 | M13: 300 | N13: 7.9 | O13: 8.4 | P13: 8.2 | Q13: 7.7 | R13: 7.1 | S13: =AVERAGE(N13:R13) -> 7.86 | T13: =_xlfn.STDEV.P(N13:R13) -> 0.44988888
B14: 313 | C14: 325 | D14: =S14 -> 8.36 | E14: =T14 -> 0.44988888 | H14: =S14 -> 8.36 | I14: =T14 -> 0.44988888 | M14: 325 | N14: 8.4 | O14: 8.9 | P14: 8.7 | Q14: 8.2 | R14: 7.6 | S14: =AVERAGE(N14:R14) -> 8.36 | T14: =_xlfn.STDEV.P(N14:R14) -> 0.44988888
B15: 337 | C15: 350 | D15: =S15 -> 8.86 | E15: =T15 -> 0.50039984 | H15: =S15 -> 8.86 | I15: =T15 -> 0.50039984 | M15: 350 | N15: 8.9 | O15: 9.4 | P15: 9.3 | Q15: 8.7 | R15: 8 | S15: =AVERAGE(N15:R15) -> 8.86 | T15: =_xlfn.STDEV.P(N15:R15) -> 0.50039984
B16: 362 | C16: 375 | D16: =S16 -> 9.3 | E16: =T16 -> 0.52535702 | F16: (Original Data) | H16: =S16 -> 9.3 | I16: =T16 -> 0.52535702 | M16: 375 | N16: 9.4 | O16: 9.9 | P16: 9.7 | Q16: 9.1 | R16: 8.4 | S16: =AVERAGE(N16:R16) -> 9.3 | T16: =_xlfn.STDEV.P(N16:R16) -> 0.52535702
B17: 388 | C17: 400 | D17: =S17 -> 9.76 | E17: =T17 -> 0.55713553 | H17: =S17 -> 9.76 | I17: =T17 -> 0.55713553 | M17: 400 | N17: 9.8 | O17: 10.4 | P17: 10.2 | Q17: 9.6 | R17: 8.8 | S17: =AVERAGE(N17:R17) -> 9.76 | T17: =_xlfn.STDEV.P(N17:R17) -> 0.55713553
B18: 416 | C18: 425 | D18: =S18 -> 10.22 | E18: =T18 -> 0.54918121 | H18: =S18 -> 10.22 | I18: =T18 -> 0.54918121 | M18: 425 | N18: 10.3 | O18: 10.9 | P18: 10.6 | Q18: 10 | R18: 9.3 | S18: =AVERAGE(N18:R18) -> 10.22 | T18: =_xlfn.STDEV.P(N18:R18) -> 0.54918121

Sheet SW6
B3: Temperature °C | C3: Cow Water Intake (L/d) | E3: Weight (kg) | F3: Finisher Water Intake (L/d) Based on Temperature °C | L3: Average (L/d) | M3: SD
B4: 4.4 | C4: 43.1 | F4: 4.4 | G4: 10 | H4: 14.4 | I4: 21.1 | J4: 26.6 | K4: 32.2
B5: 10 | C5: 47.7 | E5: 273 | F5: 22.7 | G5: 24.6 | H5: 28 | I5: 32.9 | J5: 37.9 | K5: 54.1 | L5: =AVERAGE(F5:K5) -> 33.366667 | M5: =_xlfn.STDEV.P(F5:K5) -> 10.567823
B6: 14.4 | C6: 54.9 | E6: 364 | F6: 27.6 | G6: 29.9 | H6: 34.4 | I6: 40.5 | J6: 46.6 | K6: 65.9 | L6: =AVERAGE(F6:K6) -> 40.816667 | M6: =_xlfn.STDEV.P(F6:K6) -> 12.895402
B7: 21.1 | C7: 64 | E7: 454 | F7: 32.9 | G7: 35.6 | H7: 40.9 | I7: 47.7 | J7: 54.9 | K7: 78 | L7: =AVERAGE(F7:K7) -> 48.333333 | M7: =_xlfn.STDEV.P(F7:K7) -> 15.161428
B8: 26.6 | C8: 67.8 | L8: =AVERAGE(L5:L7) -> 40.838889 | M8: =AVERAGE(M5:M7) -> 12.874884
B9: 32.2 | C9: 61.3
B10: Average | C10: =AVERAGE(C4:C9) -> 56.466667
B11: SD | C11: =_xlfn.STDEV.P(C4:C10) -> 8.1637993

Sheet SW7
A1: Parameter | B1: Unit | C1: Value | D1: SD
A2: Half-life | B2: d | C2: 108.9 | D2: 40.5
A3: Muscle:Body PFOS | C3: 0.231 | D3: 0.09
A4: Muscle:BW | C4: 0.361 | D4: 0.117
A5: Muscle:Serum Partition | C5: 0.08 | D5: =C5*0.2 -> 0.016
A6: Birth Weight | B6: kg | C6: 35.45 | D6: 3.27
A7: BW' | B7: kg | C7: 0.5584 + 2*0.001787d - 3*1.55E-06d2 - 4*1.33E-09d3 | D7: * 0.35
A8: BW > 540 days | B8: kg | C8: BW + .32 | D8: =0.32*0.35 -> 0.112
A9: Cow DMI | B9: kg | C9: -0.0001d2 + 0.0196d + 11.697 | D9: * 0.062
A10: Milk Prod (Intake) | B10: kg | C10: -0.0000000257d4+0.0000163d3-0.003686d2+0.3024d+1.445 | D10: * 0.355
A11: Soil Intake | B11: kg | C11: 0.0243 * DMI | D11: .005 * DMI
A12: Cow Water Intake | B12: L | C12: 56.47 | D12: 8.16
A13: Milk Transfer Factor | B13: d/kg | C13: 0.0213
A14: DMI ≤ 65 d | B14: kg | C14: 0
A15: DMI > 65 d | B15: kg | C15: 5.4702 * ln(d) - 22.889 | D15: BW * .0013
A16: Water Intake ≤ 240 d | B16: L | C16: 4 * DMIF
A17: Water Intake > 240 d | B17: L | C17: 40.84 | D17: 12.87

Sheet SW8
A1: AGE | B1: WEIGHT | C1: CONCPLANT | D1: CONCSOIL | E1: CONCH2O | F1: DMICOW | G1: SOIL INTAKECOW | H1: H2O INTAKECOW | I1: PFAS INTAKECOW | J1: CONCMILK | K1: INTAKEMILK | L1: DMI | M1: SOIL INTAKE | N1: H2O INTAKE | O1: PFAS INTAKEMILK | P1: PFAS INTAKEFEED | Q1: PFAS INTAKESOIL | R1: PFAS INTAKEH2O | S1: PFAS INTAKETOTAL | T1: ELIMINATION | U1: PFASBODY | V1: PFASMUSCLE | W1: PFASSERUM
A2: d | B2: kg | C2: ng/kg dry | D2: ng/kg dry | E2: ng/L | F2: kg | G2: kg | H2: L | I2: ng | J2: ng/kg | K2: kg | L2: kg | M2: kg | N2: L | O2: ng | P2: ng | Q2: ng | R2: ng | S2: ng | T2: ng | U2: ng | V2: ug/kg | W2: ug/kg
A3: 0 | B3: ='SW7'!C6 -> 35.45 | C3: 50 | D3: 550 | E3: 1.3 | F3: =-0.0001*A3^2+0.0196*A3+11.697 -> 11.697 | G3: =F3*0.0243 -> 0.2842371 | H3: ='SW7'!C$12 -> 56.47 | I3: =F3*C3+G3*D3+H3*E3 -> 814.5914 | J3: =I3*'SW7'!C$13 -> 17.350797 | K3: =-0.0000000257*A3^4+0.0000163*A3^3-0.003686*A3^2+0.3024*A3+1.445 -> 1.445 | M3: =0.0243*L3 -> 0 | N3: =4*L3 -> 0 | O3: =J3*K3 -> 25.071902 | P3: =C3*L3 -> 0 | Q3: =D3*M3 -> 0 | R3: =E3*N3 -> 0 | S3: =SUM(O3:R3) -> 25.071902 | T3: 0 | U3: 0 | V3: =(U3*'SW7'!C$3/(B3*'SW7'!C$4)/1000) -> 0 | W3: =V3/'SW7'!C$5 -> 0
A4: =A3+1 -> 1 | B4: =B3+0.5584 + 2*0.001787*A4 -3*0.00000155*A4^2 - 4*0.00000000133*A4^3 -> 36.011969 | C4: 50 | D4: 550 | E4: 1.3 | F4: =-0.0001*A4^2+0.0196*A4+11.697 -> 11.7165 | G4: =F4*0.0243 -> 0.28471095 | H4: ='SW7'!C$12 -> 56.47 | I4: =F4*C4+G4*D4+H4*E4 -> 815.82702 | J4: =I4*'SW7'!C$13 -> 17.377116 | K4: =-0.0000000257*A4^4+0.0000163*A4^3-0.003686*A4^2+0.3024*A4+1.445 -> 1.7437303 | M4: =0.0243*L4 -> 0 | N4: =4*L4 -> 0 | O4: =J4*K4 -> 30.301003 | P4: =C4*L4 -> 0 | Q4: =D4*M4 -> 0 | R4: =E4*N4 -> 0 | S4: =SUM(O4:R4) -> 30.301003 | T4: =U3-(U3*(0.5^(1/'SW7'!C$2))) -> 0 | U4: =U3+S3-T3 -> 25.071902 | V4: =(U4*'SW7'!C$3/(B4*'SW7'!C$4)/1000) -> 0.00044549741 | W4: =V4/'SW7'!C$5 -> 0.0055687176
A5: =A4+1 -> 2 | B5: =B4+0.5584 + 2*0.001787*A5 -3*0.00000155*A5^2 - 4*0.00000000133*A5^3 -> 36.577499 | C5: 50 | D5: 550 | E5: 1.3 | F5: =-0.0001*A5^2+0.0196*A5+11.697 -> 11.7358 | G5: =F5*0.0243 -> 0.28517994 | H5: ='SW7'!C$12 -> 56.47 | I5: =F5*C5+G5*D5+H5*E5 -> 817.04997 | J5: =I5*'SW7'!C$13 -> 17.403164 | K5: =-0.0000000257*A5^4+0.0000163*A5^3-0.003686*A5^2+0.3024*A5+1.445 -> 2.035186 | M5: =0.0243*L5 -> 0 | N5: =4*L5 -> 0 | O5: =J5*K5 -> 35.418676 | P5: =C5*L5 -> 0 | Q5: =D5*M5 -> 0 | R5: =E5*N5 -> 0 | S5: =SUM(O5:R5) -> 35.418676 | T5: =U4-(U4*(0.5^(1/'SW7'!C$2))) -> 0.15907556 | U5: =U4+S4-T4 -> 55.372904 | V5: =(U5*'SW7'!C$3/(B5*'SW7'!C$4)/1000) -> 0.00096869727 | W5: =V5/'SW7'!C$5 -> 0.012108716
A6: =A5+1 -> 3 | B6: =B5+0.5584 + 2*0.001787*A6 -3*0.00000155*A6^2 - 4*0.00000000133*A6^3 -> 37.146579 | C6: 50 | D6: 550 | E6: 1.3 | F6: =-0.0001*A6^2+0.0196*A6+11.697 -> 11.7549 | G6: =F6*0.0243 -> 0.28564407 | H6: ='SW7'!C$12 -> 56.47 | I6: =F6*C6+G6*D6+H6*E6 -> 818.26024 | J6: =I6*'SW7'!C$13 -> 17.428943 | K6: =-0.0000000257*A6^4+0.0000163*A6^3-0.003686*A6^2+0.3024*A6+1.445 -> 2.319464 | M6: =0.0243*L6 -> 0 | N6: =4*L6 -> 0 | O6: =J6*K6 -> 40.425806 | P6: =C6*L6 -> 0 | Q6: =D6*M6 -> 0 | R6: =E6*N6 -> 0 | S6: =SUM(O6:R6) -> 40.425806 | T6: =U5-(U5*(0.5^(1/'SW7'!C$2))) -> 0.35132858 | U6: =U5+S5-T5 -> 90.632505 | V6: =(U6*'SW7'!C$3/(B6*'SW7'!C$4)/1000) -> 0.001561241 | W6: =V6/'SW7'!C$5 -> 0.019515512
A7: =A6+1 -> 4 | B7: =B6+0.5584 + 2*0.001787*A7 -3*0.00000155*A7^2 - 4*0.00000000133*A7^3 -> 37.7192 | C7: 50 | D7: 550 | E7: 1.3 | F7: =-0.0001*A7^2+0.0196*A7+11.697 -> 11.7738 | G7: =F7*0.0243 -> 0.28610334 | H7: ='SW7'!C$12 -> 56.47 | I7: =F7*C7+G7*D7+H7*E7 -> 819.45784 | J7: =I7*'SW7'!C$13 -> 17.454452 | K7: =-0.0000000257*A7^4+0.0000163*A7^3-0.003686*A7^2+0.3024*A7+1.445 -> 2.5966606 | M7: =0.0243*L7 -> 0 | N7: =4*L7 -> 0 | O7: =J7*K7 -> 45.323288 | P7: =C7*L7 -> 0 | Q7: =D7*M7 -> 0 | R7: =E7*N7 -> 0 | S7: =SUM(O7:R7) -> 45.323288 | T7: =U6-(U6*(0.5^(1/'SW7'!C$2))) -> 0.57504278 | U7: =U6+S6-T6 -> 130.70698 | V7: =(U7*'SW7'!C$3/(B7*'SW7'!C$4)/1000) -> 0.0022173849 | W7: =V7/'SW7'!C$5 -> 0.027717312
A8: =A7+1 -> 5 | B8: =B7+0.5584 + 2*0.001787*A8 -3*0.00000155*A8^2 - 4*0.00000000133*A8^3 -> 38.295353 | C8: 50 | D8: 550 | E8: 1.3 | F8: =-0.0001*A8^2+0.0196*A8+11.697 -> 11.7925 | G8: =F8*0.0243 -> 0.28655775 | H8: ='SW7'!C$12 -> 56.47 | I8: =F8*C8+G8*D8+H8*E8 -> 820.64276 | J8: =I8*'SW7'!C$13 -> 17.479691 | K8: =-0.0000000257*A8^4+0.0000163*A8^3-0.003686*A8^2+0.3024*A8+1.445 -> 2.8668714 | M8: =0.0243*L8 -> 0 | N8: =4*L8 -> 0 | O8: =J8*K8 -> 50.112026 | P8: =C8*L8 -> 0 | Q8: =D8*M8 -> 0 | R8: =E8*N8 -> 0 | S8: =SUM(O8:R8) -> 50.112026 | T8: =U7-(U7*(0.5^(1/'SW7'!C$2))) -> 0.8293063 | U8: =U7+S7-T7 -> 175.45523 | V8: =(U8*'SW7'!C$3/(B8*'SW7'!C$4)/1000) -> 0.002931737 | W8: =V8/'SW7'!C$5 -> 0.036646713
A9: =A8+1 -> 6 | B9: =B8+0.5584 + 2*0.001787*A9 -3*0.00000155*A9^2 - 4*0.00000000133*A9^3 -> 38.875029 | C9: 50 | D9: 550 | E9: 1.3 | F9: =-0.0001*A9^2+0.0196*A9+11.697 -> 11.811 | G9: =F9*0.0243 -> 0.2870073 | H9: ='SW7'!C$12 -> 56.47 | I9: =F9*C9+G9*D9+H9*E9 -> 821.81501 | J9: =I9*'SW7'!C$13 -> 17.50466 | K9: =-0.0000000257*A9^4+0.0000163*A9^3-0.003686*A9^2+0.3024*A9+1.445 -> 3.1301915 | M9: =0.0243*L9 -> 0 | N9: =4*L9 -> 0 | O9: =J9*K9 -> 54.792937 | P9: =C9*L9 -> 0 | Q9: =D9*M9 -> 0 | R9: =E9*N9 -> 0 | S9: =SUM(O9:R9) -> 54.792937 | T9: =U8-(U8*(0.5^(1/'SW7'!C$2))) -> 1.1132238 | U9: =U8+S8-T8 -> 224.73795 | V9: =(U9*'SW7'!C$3/(B9*'SW7'!C$4)/1000) -> 0.0036992226 | W9: =V9/'SW7'!C$5 -> 0.046240283
A10: =A9+1 -> 7 | B10: =B9+0.5584 + 2*0.001787*A10 -3*0.00000155*A10^2 - 4*0.00000000133*A10^3 -> 39.458217 | C10: 50 | D10: 550 | E10: 1.3 | F10: =-0.0001*A10^2+0.0196*A10+11.697 -> 11.8293 | G10: =F10*0.0243 -> 0.28745199 | H10: ='SW7'!C$12 -> 56.47 | I10: =F10*C10+G10*D10+H10*E10 -> 822.97459 | J10: =I10*'SW7'!C$13 -> 17.529359 | K10: =-0.0000000257*A10^4+0.0000163*A10^3-0.003686*A10^2+0.3024*A10+1.445 -> 3.3867152 | M10: =0.0243*L10 -> 0 | N10: =4*L10 -> 0 | O10: =J10*K10 -> 59.366946 | P10: =C10*L10 -> 0 | Q10: =D10*M10 -> 0 | R10: =E10*N10 -> 0 | S10: =SUM(O10:R10) -> 59.366946 | T10: =U9-(U9*(0.5^(1/'SW7'!C$2))) -> 1.4259115 | U10: =U9+S9-T9 -> 278.41766 | V10: =(U10*'SW7'!C$3/(B10*'SW7'!C$4)/1000) -> 0.004515066 | W10: =V10/'SW7'!C$5 -> 0.056438325
A11: =A10+1 -> 8 | B11: =B10+0.5584 + 2*0.001787*A11 -3*0.00000155*A11^2 - 4*0.00000000133*A11^3 -> 40.044909 | C11: 50 | D11: 550 | E11: 1.3 | F11: =-0.0001*A11^2+0.0196*A11+11.697 -> 11.8474 | G11: =F11*0.0243 -> 0.28789182 | H11: ='SW7'!C$12 -> 56.47 | I11: =F11*C11+G11*D11+H11*E11 -> 824.1215 | J11: =I11*'SW7'!C$13 -> 17.553788 | K11: =-0.0000000257*A11^4+0.0000163*A11^3-0.003686*A11^2+0.3024*A11+1.445 -> 3.6365363 | M11: =0.0243*L11 -> 0 | N11: =4*L11 -> 0 | O11: =J11*K11 -> 63.834988 | P11: =C11*L11 -> 0 | Q11: =D11*M11 -> 0 | R11: =E11*N11 -> 0 | S11: =SUM(O11:R11) -> 63.834988 | T11: =U10-(U10*(0.5^(1/'SW7'!C$2))) -> 1.7664972 | U11: =U10+S10-T10 -> 336.3587 | V11: =(U11*'SW7'!C$3/(B11*'SW7'!C$4)/1000) -> 0.0053747731 | W11: =V11/'SW7'!C$5 -> 0.067184663
A12: =A11+1 -> 9 | B12: =B11+0.5584 + 2*0.001787*A12 -3*0.00000155*A12^2 - 4*0.00000000133*A12^3 -> 40.635094 | C12: 50 | D12: 550 | E12: 1.3 | F12: =-0.0001*A12^2+0.0196*A12+11.697 -> 11.8653 | G12: =F12*0.0243 -> 0.28832679 | H12: ='SW7'!C$12 -> 56.47 | I12: =F12*C12+G12*D12+H12*E12 -> 825.25573 | J12: =I12*'SW7'!C$13 -> 17.577947 | K12: =-0.0000000257*A12^4+0.0000163*A12^3-0.003686*A12^2+0.3024*A12+1.445 -> 3.8797481 | M12: =0.0243*L12 -> 0 | N12: =4*L12 -> 0 | O12: =J12*K12 -> 68.198007 | P12: =C12*L12 -> 0 | Q12: =D12*M12 -> 0 | R12: =E12*N12 -> 0 | S12: =SUM(O12:R12) -> 68.198007 | T12: =U11-(U11*(0.5^(1/'SW7'!C$2))) -> 2.13412 | U12: =U11+S11-T11 -> 398.42719 | V12: =(U12*'SW7'!C$3/(B12*'SW7'!C$4)/1000) -> 0.006274115 | W12: =V12/'SW7'!C$5 -> 0.078426437
A13: =A12+1 -> 10 | B13: =B12+0.5584 + 2*0.001787*A13 -3*0.00000155*A13^2 - 4*0.00000000133*A13^3 -> 41.228764 | C13: 50 | D13: 550 | E13: 1.3 | F13: =-0.0001*A13^2+0.0196*A13+11.697 -> 11.883 | G13: =F13*0.0243 -> 0.2887569 | H13: ='SW7'!C$12 -> 56.47 | I13: =F13*C13+G13*D13+H13*E13 -> 826.3773 | J13: =I13*'SW7'!C$13 -> 17.601836 | K13: =-0.0000000257*A13^4+0.0000163*A13^3-0.003686*A13^2+0.3024*A13+1.445 -> 4.116443 | M13: =0.0243*L13 -> 0 | N13: =4*L13 -> 0 | O13: =J13*K13 -> 72.456956 | P13: =C13*L13 -> 0 | Q13: =D13*M13 -> 0 | R13: =E13*N13 -> 0 | S13: =SUM(O13:R13) -> 72.456956 | T13: =U12-(U12*(0.5^(1/'SW7'!C$2))) -> 2.5279306 | U13: =U12+S12-T12 -> 464.49107 | V13: =(U13*'SW7'!C$3/(B13*'SW7'!C$4)/1000) -> 0.0072091131 | W13: =V13/'SW7'!C$5 -> 0.090113914
A14: =A13+1 -> 11 | B14: =B13+0.5584 + 2*0.001787*A14 -3*0.00000155*A14^2 - 4*0.00000000133*A14^3 -> 41.825908 | C14: 50 | D14: 550 | E14: 1.3 | F14: =-0.0001*A14^2+0.0196*A14+11.697 -> 11.9005 | G14: =F14*0.0243 -> 0.28918215 | H14: ='SW7'!C$12 -> 56.47 | I14: =F14*C14+G14*D14+H14*E14 -> 827.48618 | J14: =I14*'SW7'!C$13 -> 17.625456 | K14: =-0.0000000257*A14^4+0.0000163*A14^3-0.003686*A14^2+0.3024*A14+1.445 -> 4.346713 | M14: =0.0243*L14 -> 0 | N14: =4*L14 -> 0 | O14: =J14*K14 -> 76.612798 | P14: =C14*L14 -> 0 | Q14: =D14*M14 -> 0 | R14: =E14*N14 -> 0 | S14: =SUM(O14:R14) -> 76.612798 | T14: =U13-(U13*(0.5^(1/'SW7'!C$2))) -> 2.947091 | U14: =U13+S13-T13 -> 534.4201 | V14: =(U14*'SW7'!C$3/(B14*'SW7'!C$4)/1000) -> 0.0081760245 | W14: =V14/'SW7'!C$5 -> 0.10220031
A15: =A14+1 -> 12 | B15: =B14+0.5584 + 2*0.001787*A15 -3*0.00000155*A15^2 - 4*0.00000000133*A15^3 -> 42.426517 | C15: 50 | D15: 550 | E15: 1.3 | F15: =-0.0001*A15^2+0.0196*A15+11.697 -> 11.9178 | G15: =F15*0.0243 -> 0.28960254 | H15: ='SW7'!C$12 -> 56.47 | I15: =F15*C15+G15*D15+H15*E15 -> 828.5824 | J15: =I15*'SW7'!C$13 -> 17.648805 | K15: =-0.0000000257*A15^4+0.0000163*A15^3-0.003686*A15^2+0.3024*A15+1.445 -> 4.5706495 | M15: =0.0243*L15 -> 0 | N15: =4*L15 -> 0 | O15: =J15*K15 -> 80.666502 | P15: =C15*L15 -> 0 | Q15: =D15*M15 -> 0 | R15: =E15*N15 -> 0 | S15: =SUM(O15:R15) -> 80.666502 | T15: =U14-(U14*(0.5^(1/'SW7'!C$2))) -> 3.3907749 | U15: =U14+S14-T14 -> 608.08581 | V15: =(U15*'SW7'!C$3/(B15*'SW7'!C$4)/1000) -> 0.0091713288 | W15: =V15/'SW7'!C$5 -> 0.11464161
... A69: =A68+1 -> 66 | B69: =B68+0.5584 + 2*0.001787*A69 -3*0.00000155*A69^2 - 4*0.00000000133*A69^3 -> 79.724709 | C69: 30 | D69: 310 | E69: 1.3 | F69: =-0.0001*A69^2+0.0196*A69+11.697 -> 12.555 | G69: =F69*0.0243 -> 0.3050865 | H69: ='SW7'!C$12 -> 56.47 | I69: =F69*C69+G69*D69+H69*E69 -> 544.63782 | J69: =I69*'SW7'!C$13 -> 11.600785 | K69: =-0.0000000257*A69^4+0.0000163*A69^3-0.003686*A69^2+0.3024*A69+1.445 -> 9.5457181 | M69: =0.0243*L69 -> 0 | N69: =4*L69 -> 0 | O69: =J69*K69 -> 110.73783 | P69: =C69*L69 -> 0 | Q69: =D69*M69 -> 0 | R69: =E69*N69 -> 0 | S69: =SUM(O69:R69) -> 110.73783 | T69: =U68-(U68*(0.5^(1/'SW7'!C$2))) -> 37.85901 | U69: =U68+S68-T68 -> 6040.251 | V69: =(U69*'SW7'!C$3/(B69*'SW7'!C$4)/1000) -> 0.04848047 | W69: =V69/'SW7'!C$5 -> 0.60600587
A70: =A69+1 -> 67 | B70: =B69+0.5584 + 2*0.001787*A70 -3*0.00000155*A70^2 - 4*0.00000000133*A70^3 -> 80.500094 | C70: 30 | D70: 310 | E70: 1.3 | F70: =-0.0001*A70^2+0.0196*A70+11.697 -> 12.5613 | G70: =F70*0.0243 -> 0.30523959 | H70: ='SW7'!C$12 -> 56.47 | I70: =F70*C70+G70*D70+H70*E70 -> 544.87427 | J70: =I70*'SW7'!C$13 -> 11.605822 | K70: =-0.0000000257*A70^4+0.0000163*A70^3-0.003686*A70^2+0.3024*A70+1.445 -> 9.5438991 | L70: =5.4702 * LN(A70) - 22.889 -> 0.11150957 | M70: =0.0243*L70 -> 0.0027096825 | N70: =4*L70 -> 0.44603827 | O70: =J70*K70 -> 110.76479 | P70: =C70*L70 -> 3.345287 | Q70: =D70*M70 -> 0.84000157 | R70: =E70*N70 -> 0.57984975 | S70: =SUM(O70:R70) -> 115.52993 | T70: =U69-(U69*(0.5^(1/'SW7'!C$2))) -> 38.324029 | U70: =U69+S69-T69 -> 6113.1298 | V70: =(U70*'SW7'!C$3/(B70*'SW7'!C$4)/1000) -> 0.04859281 | W70: =V70/'SW7'!C$5 -> 0.60741012
A71: =A70+1 -> 68 | B71: =B70+0.5584 + 2*0.001787*A71 -3*0.00000155*A71^2 - 4*0.00000000133*A71^3 -> 81.278351 | C71: 30 | D71: 310 | E71: 1.3 | F71: =-0.0001*A71^2+0.0196*A71+11.697 -> 12.5674 | G71: =F71*0.0243 -> 0.30538782 | H71: ='SW7'!C$12 -> 56.47 | I71: =F71*C71+G71*D71+H71*E71 -> 545.10322 | J71: =I71*'SW7'!C$13 -> 11.610699 | K71: =-0.0000000257*A71^4+0.0000163*A71^3-0.003686*A71^2+0.3024*A71+1.445 -> 9.5398762 | L71: =5.4702 * LN(A71) - 22.889 -> 0.19255105 | M71: =0.0243*L71 -> 0.0046789905 | N71: =4*L71 -> 0.7702042 | O71: =J71*K71 -> 110.76463 | P71: =C71*L71 -> 5.7765315 | Q71: =D71*M71 -> 1.4504871 | R71: =E71*N71 -> 1.0012655 | S71: =SUM(O71:R71) -> 118.99291 | T71: =U70-(U70*(0.5^(1/'SW7'!C$2))) -> 38.786429 | U71: =U70+S70-T70 -> 6190.3357 | V71: =(U71*'SW7'!C$3/(B71*'SW7'!C$4)/1000) -> 0.048735351 | W71: =V71/'SW7'!C$5 -> 0.60919188
A72: =A71+1 -> 69 | B72: =B71+0.5584 + 2*0.001787*A72 -3*0.00000155*A72^2 - 4*0.00000000133*A72^3 -> 82.059471 | C72: 30 | D72: 310 | E72: 1.3 | F72: =-0.0001*A72^2+0.0196*A72+11.697 -> 12.5733 | G72: =F72*0.0243 -> 0.30553119 | H72: ='SW7'!C$12 -> 56.47 | I72: =F72*C72+G72*D72+H72*E72 -> 545.32467 | J72: =I72*'SW7'!C$13 -> 11.615415 | K72: =-0.0000000257*A72^4+0.0000163*A72^3-0.003686*A72^2+0.3024*A72+1.445 -> 9.5337057 | L72: =5.4702 * LN(A72) - 22.889 -> 0.2724094 | M72: =0.0243*L72 -> 0.0066195485 | N72: =4*L72 -> 1.0896376 | O72: =J72*K72 -> 110.73795 | P72: =C72*L72 -> 8.172282 | Q72: =D72*M72 -> 2.05206 | R72: =E72*N72 -> 1.4165289 | S72: =SUM(O72:R72) -> 122.37882 | T72: =U71-(U71*(0.5^(1/'SW7'!C$2))) -> 39.276283 | U72: =U71+S71-T71 -> 6270.5422 | V72: =(U72*'SW7'!C$3/(B72*'SW7'!C$4)/1000) -> 0.048896881 | W72: =V72/'SW7'!C$5 -> 0.61121102
A73: =A72+1 -> 70 | B73: =B72+0.5584 + 2*0.001787*A73 -3*0.00000155*A73^2 - 4*0.00000000133*A73^3 -> 82.843441 | C73: 30 | D73: 310 | E73: 1.3 | F73: =-0.0001*A73^2+0.0196*A73+11.697 -> 12.579 | G73: =F73*0.0243 -> 0.3056697 | H73: ='SW7'!C$12 -> 56.47 | I73: =F73*C73+G73*D73+H73*E73 -> 545.53861 | J73: =I73*'SW7'!C$13 -> 11.619972 | K73: =-0.0000000257*A73^4+0.0000163*A73^3-0.003686*A73^2+0.3024*A73+1.445 -> 9.525443 | L73: =5.4702 * LN(A73) - 22.889 -> 0.35111867 | M73: =0.0243*L73 -> 0.0085321838 | N73: =4*L73 -> 1.4044747 | O73: =J73*K73 -> 110.68538 | P73: =C73*L73 -> 10.53356 | Q73: =D73*M73 -> 2.644977 | R73: =E73*N73 -> 1.8258171 | S73: =SUM(O73:R73) -> 125.68974 | T73: =U72-(U72*(0.5^(1/'SW7'!C$2))) -> 39.785175 | U73: =U72+S72-T72 -> 6353.6447 | V73: =(U73*'SW7'!C$3/(B73*'SW7'!C$4)/1000) -> 0.049076047 | W73: =V73/'SW7'!C$5 -> 0.61345059
A74: =A73+1 -> 71 | B74: =B73+0.5584 + 2*0.001787*A74 -3*0.00000155*A74^2 - 4*0.00000000133*A74^3 -> 83.63025 | C74: 30 | D74: 310 | E74: 1.3 | F74: =-0.0001*A74^2+0.0196*A74+11.697 -> 12.5845 | G74: =F74*0.0243 -> 0.30580335 | H74: ='SW7'!C$12 -> 56.47 | I74: =F74*C74+G74*D74+H74*E74 -> 545.74504 | J74: =I74*'SW7'!C$13 -> 11.624369 | K74: =-0.0000000257*A74^4+0.0000163*A74^3-0.003686*A74^2+0.3024*A74+1.445 -> 9.5151431 | L74: =5.4702 * LN(A74) - 22.889 -> 0.42871146 | M74: =0.0243*L74 -> 0.010417689 | N74: =4*L74 -> 1.7148459 | O74: =J74*K74 -> 110.60754 | P74: =C74*L74 -> 12.861344 | Q74: =D74*M74 -> 3.2294835 | R74: =E74*N74 -> 2.2292996 | S74: =SUM(O74:R74) -> 128.92766 | T74: =U73-(U73*(0.5^(1/'SW7'!C$2))) -> 40.312441 | U74: =U73+S73-T73 -> 6439.5493 | V74: =(U74*'SW7'!C$3/(B74*'SW7'!C$4)/1000) -> 0.049271621 | W74: =V74/'SW7'!C$5 -> 0.61589527
A75: =A74+1 -> 72 | B75: =B74+0.5584 + 2*0.001787*A75 -3*0.00000155*A75^2 - 4*0.00000000133*A75^3 -> 84.419887 | C75: 30 | D75: 310 | E75: 1.3 | F75: =-0.0001*A75^2+0.0196*A75+11.697 -> 12.5898 | G75: =F75*0.0243 -> 0.30593214 | H75: ='SW7'!C$12 -> 56.47 | I75: =F75*C75+G75*D75+H75*E75 -> 545.94396 | J75: =I75*'SW7'!C$13 -> 11.628606 | K75: =-0.0000000257*A75^4+0.0000163*A75^3-0.003686*A75^2+0.3024*A75+1.445 -> 9.5028603 | L75: =5.4702 * LN(A75) - 22.889 -> 0.505219 | M75: =0.0243*L75 -> 0.012276822 | N75: =4*L75 -> 2.020876 | O75: =J75*K75 -> 110.50502 | P75: =C75*L75 -> 15.15657 | Q75: =D75*M75 -> 3.8058148 | R75: =E75*N75 -> 2.6271388 | S75: =SUM(O75:R75) -> 132.09455 | T75: =U74-(U74*(0.5^(1/'SW7'!C$2))) -> 40.857487 | U75: =U74+S74-T74 -> 6528.1645 | V75: =(U75*'SW7'!C$3/(B75*'SW7'!C$4)/1000) -> 0.049482439 | W75: =V75/'SW7'!C$5 -> 0.61853049
A76: =A75+1 -> 73 | B76: =B75+0.5584 + 2*0.001787*A76 -3*0.00000155*A76^2 - 4*0.00000000133*A76^3 -> 85.21234 | C76: 30 | D76: 310 | E76: 1.3 | F76: =-0.0001*A76^2+0.0196*A76+11.697 -> 12.5949 | G76: =F76*0.0243 -> 0.30605607 | H76: ='SW7'!C$12 -> 56.47 | I76: =F76*C76+G76*D76+H76*E76 -> 546.13538 | J76: =I76*'SW7'!C$13 -> 11.632684 | K76: =-0.0000000257*A76^4+0.0000163*A76^3-0.003686*A76^2+0.3024*A76+1.445 -> 9.4886483 | L76: =5.4702 * LN(A76) - 22.889 -> 0.58067123 | M76: =0.0243*L76 -> 0.014110311 | N76: =4*L76 -> 2.3226849 | O76: =J76*K76 -> 110.37844 | P76: =C76*L76 -> 17.420137 | Q76: =D76*M76 -> 4.3741964 | R76: =E76*N76 -> 3.0194904 | S76: =SUM(O76:R76) -> 135.19227 | T76: =U75-(U75*(0.5^(1/'SW7'!C$2))) -> 41.41973 | U76: =U75+S75-T75 -> 6619.4016 | V76: =(U76*'SW7'!C$3/(B76*'SW7'!C$4)/1000) -> 0.049707396 | W76: =V76/'SW7'!C$5 -> 0.62134246
A77: =A76+1 -> 74 | B77: =B76+0.5584 + 2*0.001787*A77 -3*0.00000155*A77^2 - 4*0.00000000133*A77^3 -> 86.007596 | C77: 30 | D77: 310 | E77: 1.3 | F77: =-0.0001*A77^2+0.0196*A77+11.697 -> 12.5998 | G77: =F77*0.0243 -> 0.30617514 | H77: ='SW7'!C$12 -> 56.47 | I77: =F77*C77+G77*D77+H77*E77 -> 546.31929 | J77: =I77*'SW7'!C$13 -> 11.636601 | K77: =-0.0000000257*A77^4+0.0000163*A77^3-0.003686*A77^2+0.3024*A77+1.445 -> 9.4725602 | L77: =5.4702 * LN(A77) - 22.889 -> 0.65509687 | M77: =0.0243*L77 -> 0.015918854 | N77: =4*L77 -> 2.6203875 | O77: =J77*K77 -> 110.2284 | P77: =C77*L77 -> 19.652906 | Q77: =D77*M77 -> 4.9348447 | R77: =E77*N77 -> 3.4065037 | S77: =SUM(O77:R77) -> 138.22266 | T77: =U76-(U76*(0.5^(1/'SW7'!C$2))) -> 41.998609 | U77: =U76+S76-T76 -> 6713.1741 | V77: =(U77*'SW7'!C$3/(B77*'SW7'!C$4)/1000) -> 0.049945444 | W77: =V77/'SW7'!C$5 -> 0.62431805
A78: =A77+1 -> 75 | B78: =B77+0.5584 + 2*0.001787*A78 -3*0.00000155*A78^2 - 4*0.00000000133*A78^3 -> 86.805646 | C78: 30 | D78: 310 | E78: 1.3 | F78: =-0.0001*A78^2+0.0196*A78+11.697 -> 12.6045 | G78: =F78*0.0243 -> 0.30628935 | H78: ='SW7'!C$12 -> 56.47 | I78: =F78*C78+G78*D78+H78*E78 -> 546.4957 | J78: =I78*'SW7'!C$13 -> 11.640358 | K78: =-0.0000000257*A78^4+0.0000163*A78^3-0.003686*A78^2+0.3024*A78+1.445 -> 9.4546484 | L78: =5.4702 * LN(A78) - 22.889 -> 0.72852348 | M78: =0.0243*L78 -> 0.017703121 | N78: =4*L78 -> 2.9140939 | O78: =J78*K78 -> 110.0555 | P78: =C78*L78 -> 21.855704 | Q78: =D78*M78 -> 5.4879674 | R78: =E78*N78 -> 3.7883221 | S78: =SUM(O78:R78) -> 141.18749 | T78: =U77-(U77*(0.5^(1/'SW7'!C$2))) -> 42.593574 | U78: =U77+S77-T77 -> 6809.3982 | V78: =(U78*'SW7'!C$3/(B78*'SW7'!C$4)/1000) -> 0.050195587 | W78: =V78/'SW7'!C$5 -> 0.62744483
A79: =A78+1 -> 76 | B79: =B78+0.5584 + 2*0.001787*A79 -3*0.00000155*A79^2 - 4*0.00000000133*A79^3 -> 87.606476 | C79: 30 | D79: 310 | E79: 1.3 | F79: =-0.0001*A79^2+0.0196*A79+11.697 -> 12.609 | G79: =F79*0.0243 -> 0.3063987 | H79: ='SW7'!C$12 -> 56.47 | I79: =F79*C79+G79*D79+H79*E79 -> 546.6646 | J79: =I79*'SW7'!C$13 -> 11.643956 | K79: =-0.0000000257*A79^4+0.0000163*A79^3-0.003686*A79^2+0.3024*A79+1.445 -> 9.4349649 | L79: =5.4702 * LN(A79) - 22.889 -> 0.80097752 | M79: =0.0243*L79 -> 0.019463754 | N79: =4*L79 -> 3.2039101 | O79: =J79*K79 -> 109.86032 | P79: =C79*L79 -> 24.029326 | Q79: =D79*M79 -> 6.0337636 | R79: =E79*N79 -> 4.1650831 | S79: =SUM(O79:R79) -> 144.08849 | T79: =U78-(U78*(0.5^(1/'SW7'!C$2))) -> 43.204094 | U79: =U78+S78-T78 -> 6907.9921 | V79: =(U79*'SW7'!C$3/(B79*'SW7'!C$4)/1000) -> 0.050456881 | W79: =V79/'SW7'!C$5 -> 0.63071101
A80: =A79+1 -> 77 | B80: =B79+0.5584 + 2*0.001787*A80 -3*0.00000155*A80^2 - 4*0.00000000133*A80^3 -> 88.410075 | C80: 30 | D80: 310 | E80: 1.3 | F80: =-0.0001*A80^2+0.0196*A80+11.697 -> 12.6133 | G80: =F80*0.0243 -> 0.30650319 | H80: ='SW7'!C$12 -> 56.47 | I80: =F80*C80+G80*D80+H80*E80 -> 546.82599 | J80: =I80*'SW7'!C$13 -> 11.647394 | K80: =-0.0000000257*A80^4+0.0000163*A80^3-0.003686*A80^2+0.3024*A80+1.445 -> 9.4135607 | L80: =5.4702 * LN(A80) - 22.889 -> 0.87248442 | M80: =0.0243*L80 -> 0.021201371 | N80: =4*L80 -> 3.4899377 | O80: =J80*K80 -> 109.64345 | P80: =C80*L80 -> 26.174533 | Q80: =D80*M80 -> 6.5724251 | R80: =E80*N80 -> 4.536919 | S80: =SUM(O80:R80) -> 146.92732 | T80: =U79-(U79*(0.5^(1/'SW7'!C$2))) -> 43.82965 | U80: =U79+S79-T79 -> 7008.8765 | V80: =(U80*'SW7'!C$3/(B80*'SW7'!C$4)/1000) -> 0.05072843 | W80: =V80/'SW7'!C$5 -> 0.63410538
A81: =A80+1 -> 78 | B81: =B80+0.5584 + 2*0.001787*A81 -3*0.00000155*A81^2 - 4*0.00000000133*A81^3 -> 89.216432 | C81: 30 | D81: 310 | E81: 1.3 | F81: =-0.0001*A81^2+0.0196*A81+11.697 -> 12.6174 | G81: =F81*0.0243 -> 0.30660282 | H81: ='SW7'!C$12 -> 56.47 | I81: =F81*C81+G81*D81+H81*E81 -> 546.97987 | J81: =I81*'SW7'!C$13 -> 11.650671 | K81: =-0.0000000257*A81^4+0.0000163*A81^3-0.003686*A81^2+0.3024*A81+1.445 -> 9.3904867 | L81: =5.4702 * LN(A81) - 22.889 -> 0.94306862 | M81: =0.0243*L81 -> 0.022916568 | N81: =4*L81 -> 3.7722745 | O81: =J81*K81 -> 109.40547 | P81: =C81*L81 -> 28.292059 | Q81: =D81*M81 -> 7.1041359 | R81: =E81*N81 -> 4.9039568 | S81: =SUM(O81:R81) -> 149.70563 | T81: =U80-(U80*(0.5^(1/'SW7'!C$2))) -> 44.469739 | U81: =U80+S80-T80 -> 7111.9741 | V81: =(U81*'SW7'!C$3/(B81*'SW7'!C$4)/1000) -> 0.051009386 | W81: =V81/'SW7'!C$5 -> 0.63761732
... A242: =A241+1 -> 239 | B242: =B241+0.5584 + 2*0.001787*A242 -3*0.00000155*A242^2 - 4*0.00000000133*A242^3 -> 245.74053 | C242: 1200 | D242: 0 | E242: 1.3 | F242: =-0.0001*A242^2+0.0196*A242+11.697 -> 10.6693 | G242: =F242*0.0243 -> 0.25926399 | H242: ='SW7'!C$12 -> 56.47 | I242: =F242*C242+G242*D242+H242*E242 -> 12876.571 | J242: =I242*'SW7'!C$13 -> 274.27096 | K242: =-0.0000000257*A242^4+0.0000163*A242^3-0.003686*A242^2+0.3024*A242+1.445 -> 1.8426916 | L242: =5.4702 * LN(A242) - 22.889 -> 7.0683509 | M242: =0.0243*L242 -> 0.17176093 | N242: =4*L242 -> 28.273404 | O242: =J242*K242 -> 505.39681 | P242: =C242*L242 -> 8482.0211 | Q242: =D242*M242 -> 0 | R242: =E242*N242 -> 36.755425 | S242: =SUM(O242:R242) -> 9024.1733 | T242: =U241-(U241*(0.5^(1/'SW7'!C$2))) -> 6731.8774 | U242: =U241+S241-T241 -> 1063310.9 | V242: =(U242*'SW7'!C$3/(B242*'SW7'!C$4)/1000) -> 2.7687787 | W242: =V242/'SW7'!C$5 -> 34.609734
A243: =A242+1 -> 240 | B243: =B242+0.5584 + 2*0.001787*A243 -3*0.00000155*A243^2 - 4*0.00000000133*A243^3 -> 246.8153 | C243: 1200 | D243: 0 | E243: 1.3 | L243: =5.4702 * LN(A243) - 22.889 -> 7.091191 | M243: =0.0243*L243 -> 0.17231594 | N243: =4*L243 -> 28.364764 | O243: =J243*K243 -> 0 | P243: =C243*L243 -> 8509.4292 | Q243: =D243*M243 -> 0 | R243: =E243*N243 -> 36.874193 | S243: =SUM(O243:R243) -> 8546.3034 | T243: =U242-(U242*(0.5^(1/'SW7'!C$2))) -> 6746.4676 | U243: =U242+S242-T242 -> 1065603.2 | V243: =(U243*'SW7'!C$3/(B243*'SW7'!C$4)/1000) -> 2.7626648 | W243: =V243/'SW7'!C$5 -> 34.533311
A244: =A243+1 -> 241 | B244: =B243+0.5584 + 2*0.001787*A244 -3*0.00000155*A244^2 - 4*0.00000000133*A244^3 -> 247.8905 | C244: 1200 | D244: 0 | E244: 1.3 | L244: =5.4702 * LN(A244) - 22.889 -> 7.1139362 | M244: =0.0243*L244 -> 0.17286865 | N244: =4*L244 -> 28.455745 | O244: =J244*K244 -> 0 | P244: =C244*L244 -> 8536.7234 | Q244: =D244*M244 -> 0 | R244: =E244*N244 -> 36.992468 | S244: =SUM(O244:R244) -> 8573.7159 | T244: =U243-(U243*(0.5^(1/'SW7'!C$2))) -> 6761.0117 | U244: =U243+S243-T243 -> 1067403 | V244: =(U244*'SW7'!C$3/(B244*'SW7'!C$4)/1000) -> 2.7553282 | W244: =V244/'SW7'!C$5 -> 34.441602
A245: =A244+1 -> 242 | B245: =B244+0.5584 + 2*0.001787*A245 -3*0.00000155*A245^2 - 4*0.00000000133*A245^3 -> 248.96608 | C245: 1200 | D245: 0 | E245: 1.3 | L245: =5.4702 * LN(A245) - 22.889 -> 7.1365871 | M245: =0.0243*L245 -> 0.17341907 | N245: =4*L245 -> 28.546349 | O245: =J245*K245 -> 0 | P245: =C245*L245 -> 8563.9046 | Q245: =D245*M245 -> 0 | R245: =E245*N245 -> 37.110253 | S245: =SUM(O245:R245) -> 8601.0148 | T245: =U244-(U244*(0.5^(1/'SW7'!C$2))) -> 6772.4312 | U245: =U244+S244-T244 -> 1069215.7 | V245: =(U245*'SW7'!C$3/(B245*'SW7'!C$4)/1000) -> 2.7480835 | W245: =V245/'SW7'!C$5 -> 34.351044
A246: =A245+1 -> 243 | B246: =B245+0.5584 + 2*0.001787*A246 -3*0.00000155*A246^2 - 4*0.00000000133*A246^3 -> 250.04205 | C246: 1200 | D246: 0 | E246: 1.3 | L246: =5.4702 * LN(A246) - 22.889 -> 7.1591447 | M246: =0.0243*L246 -> 0.17396722 | N246: =4*L246 -> 28.636579 | O246: =J246*K246 -> 0 | P246: =C246*L246 -> 8590.9736 | Q246: =D246*M246 -> 0 | R246: =E246*N246 -> 37.227552 | S246: =SUM(O246:R246) -> 8628.2012 | T246: =U245-(U245*(0.5^(1/'SW7'!C$2))) -> 6783.9324 | U246: =U245+S245-T245 -> 1071044.3 | V246: =(U246*'SW7'!C$3/(B246*'SW7'!C$4)/1000) -> 2.7409377 | W246: =V246/'SW7'!C$5 -> 34.261721
A247: =A246+1 -> 244 | B247: =B246+0.5584 + 2*0.001787*A247 -3*0.00000155*A247^2 - 4*0.00000000133*A247^3 -> 251.11838 | C247: 1200 | D247: 0 | E247: 1.3 | L247: =5.4702 * LN(A247) - 22.889 -> 7.1816096 | M247: =0.0243*L247 -> 0.17451311 | N247: =4*L247 -> 28.726439 | O247: =J247*K247 -> 0 | P247: =C247*L247 -> 8617.9316 | Q247: =D247*M247 -> 0 | R247: =E247*N247 -> 37.34437 | S247: =SUM(O247:R247) -> 8655.2759 | T247: =U246-(U246*(0.5^(1/'SW7'!C$2))) -> 6795.5344 | U247: =U246+S246-T246 -> 1072888.6 | V247: =(U247*'SW7'!C$3/(B247*'SW7'!C$4)/1000) -> 2.7338891 | W247: =V247/'SW7'!C$5 -> 34.173614
A248: =A247+1 -> 245 | B248: =B247+0.5584 + 2*0.001787*A248 -3*0.00000155*A248^2 - 4*0.00000000133*A248^3 -> 252.19506 | C248: 1200 | D248: 0 | E248: 1.3 | L248: =5.4702 * LN(A248) - 22.889 -> 7.2039827 | M248: =0.0243*L248 -> 0.17505678 | N248: =4*L248 -> 28.815931 | O248: =J248*K248 -> 0 | P248: =C248*L248 -> 8644.7792 | Q248: =D248*M248 -> 0 | R248: =E248*N248 -> 37.46071 | S248: =SUM(O248:R248) -> 8682.2399 | T248: =U247-(U247*(0.5^(1/'SW7'!C$2))) -> 6807.2358 | U248: =U247+S247-T247 -> 1074748.3 | V248: =(U248*'SW7'!C$3/(B248*'SW7'!C$4)/1000) -> 2.7269362 | W248: =V248/'SW7'!C$5 -> 34.086703
A249: =A248+1 -> 246 | B249: =B248+0.5584 + 2*0.001787*A249 -3*0.00000155*A249^2 - 4*0.00000000133*A249^3 -> 253.27207 | C249: 1200 | D249: 0 | E249: 1.3 | L249: =5.4702 * LN(A249) - 22.889 -> 7.2262646 | M249: =0.0243*L249 -> 0.17559823 | N249: =4*L249 -> 28.905058 | O249: =J249*K249 -> 0 | P249: =C249*L249 -> 8671.5175 | Q249: =D249*M249 -> 0 | R249: =E249*N249 -> 37.576576 | S249: =SUM(O249:R249) -> 8709.0941 | T249: =U248-(U248*(0.5^(1/'SW7'!C$2))) -> 6819.0355 | U249: =U248+S248-T248 -> 1076623.3 | V249: =(U249*'SW7'!C$3/(B249*'SW7'!C$4)/1000) -> 2.7200774 | W249: =V249/'SW7'!C$5 -> 34.000968
A250: =A249+1 -> 247 | B250: =B249+0.5584 + 2*0.001787*A250 -3*0.00000155*A250^2 - 4*0.00000000133*A250^3 -> 254.34938 | C250: 1200 | D250: 0 | E250: 1.3 | L250: =5.4702 * LN(A250) - 22.889 -> 7.2484561 | M250: =0.0243*L250 -> 0.17613748 | N250: =4*L250 -> 28.993824 | O250: =J250*K250 -> 0 | P250: =C250*L250 -> 8698.1473 | Q250: =D250*M250 -> 0 | R250: =E250*N250 -> 37.691972 | S250: =SUM(O250:R250) -> 8735.8393 | T250: =U249-(U249*(0.5^(1/'SW7'!C$2))) -> 6830.9319 | U250: =U249+S249-T249 -> 1078513.4 | V250: =(U250*'SW7'!C$3/(B250*'SW7'!C$4)/1000) -> 2.7133113 | W250: =V250/'SW7'!C$5 -> 33.916392
A251: =A250+1 -> 248 | B251: =B250+0.5584 + 2*0.001787*A251 -3*0.00000155*A251^2 - 4*0.00000000133*A251^3 -> 255.427 | C251: 1200 | D251: 0 | E251: 1.3 | L251: =5.4702 * LN(A251) - 22.889 -> 7.2705579 | M251: =0.0243*L251 -> 0.17667456 | N251: =4*L251 -> 29.082232 | O251: =J251*K251 -> 0 | P251: =C251*L251 -> 8724.6695 | Q251: =D251*M251 -> 0 | R251: =E251*N251 -> 37.806901 | S251: =SUM(O251:R251) -> 8762.4764 | T251: =U250-(U250*(0.5^(1/'SW7'!C$2))) -> 6842.9239 | U251: =U250+S250-T250 -> 1080418.3 | V251: =(U251*'SW7'!C$3/(B251*'SW7'!C$4)/1000) -> 2.7066363 | W251: =V251/'SW7'!C$5 -> 33.832954
A252: =A251+1 -> 249 | B252: =B251+0.5584 + 2*0.001787*A252 -3*0.00000155*A252^2 - 4*0.00000000133*A252^3 -> 256.50489 | C252: 1200 | D252: 0 | E252: 1.3 | L252: =5.4702 * LN(A252) - 22.889 -> 7.2925708 | M252: =0.0243*L252 -> 0.17720947 | N252: =4*L252 -> 29.170283 | O252: =J252*K252 -> 0 | P252: =C252*L252 -> 8751.085 | Q252: =D252*M252 -> 0 | R252: =E252*N252 -> 37.921368 | S252: =SUM(O252:R252) -> 8789.0064 | T252: =U251-(U251*(0.5^(1/'SW7'!C$2))) -> 6855.0101 | U252: =U251+S251-T251 -> 1082337.8 | V252: =(U252*'SW7'!C$3/(B252*'SW7'!C$4)/1000) -> 2.7000511 | W252: =V252/'SW7'!C$5 -> 33.750638
A253: =A252+1 -> 250 | B253: =B252+0.5584 + 2*0.001787*A253 -3*0.00000155*A253^2 - 4*0.00000000133*A253^3 -> 257.58304 | C253: 1200 | D253: 0 | E253: 1.3 | L253: =5.4702 * LN(A253) - 22.889 -> 7.3144955 | M253: =0.0243*L253 -> 0.17774224 | N253: =4*L253 -> 29.257982 | O253: =J253*K253 -> 0 | P253: =C253*L253 -> 8777.3946 | Q253: =D253*M253 -> 0 | R253: =E253*N253 -> 38.035377 | S253: =SUM(O253:R253) -> 8815.43 | T253: =U252-(U252*(0.5^(1/'SW7'!C$2))) -> 6867.1893 | U253: =U252+S252-T252 -> 1084271.8 | V253: =(U253*'SW7'!C$3/(B253*'SW7'!C$4)/1000) -> 2.6935541 | W253: =V253/'SW7'!C$5 -> 33.669426
...

Sheet SW9
A1: Age (d) | B1: Muscle PFOS
A2: 675 | B2: 2.87
B4: Mean | C4: 0.05 | D4: 0.95 | E4: Pos Err | F4: Neg Err
A5: 675 | B5: 1.89 | C5: 0.91 | D5: 2.87 | E5: =D5-B5 -> 0.98 | F5: =B5-C5 -> 0.98

Sheet SW10
A1: AGE | B1: WEIGHT | C1: CONCF | D1: CONCS | E1: CONCW | F1: DMICOW | G1: SOIL INTAKECOW | H1: WATER INTAKECOW | I1: PFAS INTAKECOW | J1: CONCMILK | K1: INTAKEMILK | L1: DMI | M1: SOIL INTAKE | N1: WATER INTAKE | O1: PFAS INTAKEMILK | P1: PFAS INTAKEF | Q1: PFAS INTAKES | R1: PFAS INTAKEW | S1: PFAS INTAKETOTAL | T1: ELIMINATION | U1: PFASBODY | V1: PFASMUSCLE | W1: PFASSERUM
A2: d | B2: kg | C2: ng/kg dry | D2: ng/kg dry | E2: ng/L | F2: kg | G2: kg | H2: L | I2: ng | J2: ng/kg | K2: kg | L2: kg | M2: kg | N2: L | O2: ng | P2: ng | Q2: ng | R2: ng | S2: ng | T2: ng | U2: ng | V2: ug/kg | W2: ug/kg
A3: 0 | B3: {=_xll.RiskNormal('SW7'!C6,'SW7'!D6,_xll.RiskTruncateP(0.05,0.95),_xll.RiskName("Birth Weight"),_xll.RiskUnits("kg"))} -> #NAME? | C3: {=_xll.RiskNormal(50,50*0.3941,_xll.RiskTruncateP(0.05,0.95),_xll.RiskName("Diet 1 Feed"),_xll.RiskUnits("ng/kg dry"))} -> #NAME? | D3: {=_xll.RiskNormal(550,550*0.282,_xll.RiskTruncateP(0.05,0.95),_xll.RiskName("Diet 1 Soil"),_xll.RiskUnits("ng/kg dry"))} -> #NAME? | E3: 1.3 | F3: {=_xll.RiskNormal((-0.0001*A3^2+0.0196*A3+11.697),(-0.0001*A3^2+0.0196*A3+11.697)*0.062,_xll.RiskTruncateP(0.05,0.95),_xll.RiskName("DMI Cow"),_xll.RiskUnits("kg"))} -> #NAME? | G3: {=_xll.RiskNormal(F3*0.0243,F3*0.005,_xll.RiskTruncateP(0.05,0.95),_xll.RiskName("Soil Intake Cow"),_xll.RiskUnits("kg"))} -> #NAME? | H3: {=_xll.RiskNormal('SW7'!C$12,'SW7'!D$12,_xll.RiskTruncateP(0.05,0.95),_xll.RiskName("Water Intake Cow"),_xll.RiskUnits("L"))} -> #NAME? | I3: =F3*C3+G3*D3+H3*E3 -> #NAME? | J3: =I3*0.0213 -> #NAME? | K3: 0 | M3: {=_xll.RiskNormal(0.0243*L3,0.005*L3,_xll.RiskTruncateP(0.05,0.95),_xll.RiskName("Soil Intake"),_xll.RiskUnits("kg"))} -> #NAME? | N3: =4*L3 -> 0 | O3: =J3*K3 -> #NAME? | P3: =C3*L3 -> #NAME? | Q3: =D3*M3 -> #NAME? | R3: =E3*N3 -> 0 | S3: =SUM(O3:R3) -> #NAME? | T3: 0 | U3: 0 | V3: {=(U3*_xll.RiskNormal('SW7'!C$3,'SW7'!D$3,_xll.RiskTruncateP(0.05,0.95),_xll.RiskName("PFAS MUSCLE FRAC"))/(B3*_xll.RiskNormal('SW7'!C$4,'SW7'!E$4,_xll.RiskTruncateP(0.05,0.95),_xll.RiskName("MUSCLE BW FRAC"))))/1000} -> #NAME? | W3: {=V3/_xll.RiskNormal('SW7'!C$5,'SW7'!D$5,_xll.RiskTruncateP(0.05,0.95),_xll.RiskName("Serum Part"))} -> #NAME?
A4: =A3+1 -> 1 | B4: {=B3+_xll.RiskNormal(0.5584 + 2*0.001787*A4 -3*0.00000155*A4^2 - 4*0.00000000133*A4^3,0.35*(0.5584 + 2*0.001787*A4 -3*0.00000155*A4^2 - 4*0.00000000133*A4^3),_xll.RiskTruncateP(0.05,0.95),_xll.RiskName("BW Gain"),_xll.RiskUnits("kg"))} -> #NAME? | C4: {=_xll.RiskNormal(50,50*0.3941,_xll.RiskTruncateP(0.05,0.95),_xll.RiskName("Diet 1 Feed"),_xll.RiskUnits("ng/kg dry"))} -> #NAME? | D4: {=_xll.RiskNormal(550,550*0.282,_xll.RiskTruncateP(0.05,0.95),_xll.RiskName("Diet 1 Soil"),_xll.RiskUnits("ng/kg dry"))} -> #NAME? | E4: 1.3 | F4: {=_xll.RiskNormal((-0.0001*A4^2+0.0196*A4+11.697),(-0.0001*A4^2+0.0196*A4+11.697)*0.062,_xll.RiskTruncateP(0.05,0.95),_xll.RiskName("DMI Cow"),_xll.RiskUnits("kg"))} -> #NAME? | G4: {=_xll.RiskNormal(F4*0.0243,F4*0.005,_xll.RiskTruncateP(0.05,0.95),_xll.RiskName("Soil Intake Cow"),_xll.RiskUnits("kg"))} -> #NAME? | H4: {=_xll.RiskNormal('SW7'!C$12,'SW7'!D$12,_xll.RiskTruncateP(0.05,0.95),_xll.RiskName("Water Intake Cow"),_xll.RiskUnits("L"))} -> #NAME? | I4: =F4*C4+G4*D4+H4*E4 -> #NAME? | J4: =I4*0.0213 -> #NAME? | K4: {=_xll.RiskNormal(-0.0000000257*A4^4+0.0000163*A4^3-0.003686*A4^2+0.3024*A4+1.445,(-0.0000000257*A4^4+0.0000163*A4^3-0.003686*A4^2+0.3024*A4+1.445)*0.355,_xll.RiskTruncateP(0.05,0.95),_xll.RiskName("Milk Intake"),_xll.RiskUnits("kg"))} -> #NAME? | M4: {=_xll.RiskNormal(0.0243*L4,0.005*L4,_xll.RiskTruncateP(0.05,0.95),_xll.RiskName("Soil Intake"),_xll.RiskUnits("kg"))} -> #NAME? | N4: =4*L4 -> 0 | O4: =J4*K4 -> #NAME? | P4: =C4*L4 -> #NAME? | Q4: =D4*M4 -> #NAME? | R4: =E4*N4 -> 0 | S4: =SUM(O4:R4) -> #NAME? | T4: {=U3-(U3*(0.5^(1/_xll.RiskNormal('SW7'!C$2,'SW7'!D$2,_xll.RiskTruncateP(0.05,0.95),_xll.RiskName("Halflife"),_xll.RiskUnits("d")))))} -> #NAME? | U4: =U3+S3-T3 -> #NAME? | V4: {=(U4*_xll.RiskNormal('SW7'!C$3,'SW7'!D$3,_xll.RiskTruncateP(0.05,0.95),_xll.RiskName("PFAS MUSCLE FRAC"))/(B4*_xll.RiskNormal('SW7'!C$4,'SW7'!E$4,_xll.RiskTruncateP(0.05,0.95),_xll.RiskName("MUSCLE BW FRAC"))))/1000} -> #NAME? | W4: {=V4/_xll.RiskNormal('SW7'!C$5,'SW7'!D$5,_xll.RiskTruncateP(0.05,0.95),_xll.RiskName("Serum Part"))} -> #NAME?
A5: =A4+1 -> 2 | B5: {=B4+_xll.RiskNormal(0.5584 + 2*0.001787*A5 -3*0.00000155*A5^2 - 4*0.00000000133*A5^3,0.35*(0.5584 + 2*0.001787*A5 -3*0.00000155*A5^2 - 4*0.00000000133*A5^3),_xll.RiskTruncateP(0.05,0.95),_xll.RiskName("BW Gain"),_xll.RiskUnits("kg"))} -> #NAME? | C5: {=_xll.RiskNormal(50,50*0.3941,_xll.RiskTruncateP(0.05,0.95),_xll.RiskName("Diet 1 Feed"),_xll.RiskUnits("ng/kg dry"))} -> #NAME? | D5: {=_xll.RiskNormal(550,550*0.282,_xll.RiskTruncateP(0.05,0.95),_xll.RiskName("Diet 1 Soil"),_xll.RiskUnits("ng/kg dry"))} -> #NAME? | E5: 1.3 | F5: {=_xll.RiskNormal((-0.0001*A5^2+0.0196*A5+11.697),(-0.0001*A5^2+0.0196*A5+11.697)*0.062,_xll.RiskTruncateP(0.05,0.95),_xll.RiskName("DMI Cow"),_xll.RiskUnits("kg"))} -> #NAME? | G5: {=_xll.RiskNormal(F5*0.0243,F5*0.005,_xll.RiskTruncateP(0.05,0.95),_xll.RiskName("Soil Intake Cow"),_xll.RiskUnits("kg"))} -> #NAME? | H5: {=_xll.RiskNormal('SW7'!C$12,'SW7'!D$12,_xll.RiskTruncateP(0.05,0.95),_xll.RiskName("Water Intake Cow"),_xll.RiskUnits("L"))} -> #NAME? | I5: =F5*C5+G5*D5+H5*E5 -> #NAME? | J5: =I5*0.0213 -> #NAME? | K5: {=_xll.RiskNormal(-0.0000000257*A5^4+0.0000163*A5^3-0.003686*A5^2+0.3024*A5+1.445,(-0.0000000257*A5^4+0.0000163*A5^3-0.003686*A5^2+0.3024*A5+1.445)*0.355,_xll.RiskTruncateP(0.05,0.95),_xll.RiskName("Milk Intake"),_xll.RiskUnits("kg"))} -> #NAME? | M5: {=_xll.RiskNormal(0.0243*L5,0.005*L5,_xll.RiskTruncateP(0.05,0.95),_xll.RiskName("Soil Intake"),_xll.RiskUnits("kg"))} -> #NAME? | N5: =4*L5 -> 0 | O5: =J5*K5 -> #NAME? | P5: =C5*L5 -> #NAME? | Q5: =D5*M5 -> #NAME? | R5: =E5*N5 -> 0 | S5: =SUM(O5:R5) -> #NAME? | T5: {=U4-(U4*(0.5^(1/_xll.RiskNormal('SW7'!C$2,'SW7'!D$2,_xll.RiskTruncateP(0.05,0.95),_xll.RiskName("Halflife"),_xll.RiskUnits("d")))))} -> #NAME? | U5: =U4+S4-T4 -> #NAME? | V5: {=(U5*_xll.RiskNormal('SW7'!C$3,'SW7'!D$3,_xll.RiskTruncateP(0.05,0.95),_xll.RiskName("PFAS MUSCLE FRAC"))/(B5*_xll.RiskNormal('SW7'!C$4,'SW7'!E$4,_xll.RiskTruncateP(0.05,0.95),_xll.RiskName("MUSCLE BW FRAC"))))/1000} -> #NAME? | W5: {=V5/_xll.RiskNormal('SW7'!C$5,'SW7'!D$5,_xll.RiskTruncateP(0.05,0.95),_xll.RiskName("Serum Part"))} -> #NAME?
A6: =A5+1 -> 3 | B6: {=B5+_xll.RiskNormal(0.5584 + 2*0.001787*A6 -3*0.00000155*A6^2 - 4*0.00000000133*A6^3,0.35*(0.5584 + 2*0.001787*A6 -3*0.00000155*A6^2 - 4*0.00000000133*A6^3),_xll.RiskTruncateP(0.05,0.95),_xll.RiskName("BW Gain"),_xll.RiskUnits("kg"))} -> #NAME? | C6: {=_xll.RiskNormal(50,50*0.3941,_xll.RiskTruncateP(0.05,0.95),_xll.RiskName("Diet 1 Feed"),_xll.RiskUnits("ng/kg dry"))} -> #NAME? | D6: {=_xll.RiskNormal(550,550*0.282,_xll.RiskTruncateP(0.05,0.95),_xll.RiskName("Diet 1 Soil"),_xll.RiskUnits("ng/kg dry"))} -> #NAME? | E6: 1.3 | F6: {=_xll.RiskNormal((-0.0001*A6^2+0.0196*A6+11.697),(-0.0001*A6^2+0.0196*A6+11.697)*0.062,_xll.RiskTruncateP(0.05,0.95),_xll.RiskName("DMI Cow"),_xll.RiskUnits("kg"))} -> #NAME? | G6: {=_xll.RiskNormal(F6*0.0243,F6*0.005,_xll.RiskTruncateP(0.05,0.95),_xll.RiskName("Soil Intake Cow"),_xll.RiskUnits("kg"))} -> #NAME? | H6: {=_xll.RiskNormal('SW7'!C$12,'SW7'!D$12,_xll.RiskTruncateP(0.05,0.95),_xll.RiskName("Water Intake Cow"),_xll.RiskUnits("L"))} -> #NAME? | I6: =F6*C6+G6*D6+H6*E6 -> #NAME? | J6: =I6*0.0213 -> #NAME? | K6: {=_xll.RiskNormal(-0.0000000257*A6^4+0.0000163*A6^3-0.003686*A6^2+0.3024*A6+1.445,(-0.0000000257*A6^4+0.0000163*A6^3-0.003686*A6^2+0.3024*A6+1.445)*0.355,_xll.RiskTruncateP(0.05,0.95),_xll.RiskName("Milk Intake"),_xll.RiskUnits("kg"))} -> #NAME? | M6: {=_xll.RiskNormal(0.0243*L6,0.005*L6,_xll.RiskTruncateP(0.05,0.95),_xll.RiskName("Soil Intake"),_xll.RiskUnits("kg"))} -> #NAME? | N6: =4*L6 -> 0 | O6: =J6*K6 -> #NAME? | P6: =C6*L6 -> #NAME? | Q6: =D6*M6 -> #NAME? | R6: =E6*N6 -> 0 | S6: =SUM(O6:R6) -> #NAME? | T6: {=U5-(U5*(0.5^(1/_xll.RiskNormal('SW7'!C$2,'SW7'!D$2,_xll.RiskTruncateP(0.05,0.95),_xll.RiskName("Halflife"),_xll.RiskUnits("d")))))} -> #NAME? | U6: =U5+S5-T5 -> #NAME? | V6: {=(U6*_xll.RiskNormal('SW7'!C$3,'SW7'!D$3,_xll.RiskTruncateP(0.05,0.95),_xll.RiskName("PFAS MUSCLE FRAC"))/(B6*_xll.RiskNormal('SW7'!C$4,'SW7'!E$4,_xll.RiskTruncateP(0.05,0.95),_xll.RiskName("MUSCLE BW FRAC"))))/1000} -> #NAME? | W6: {=V6/_xll.RiskNormal('SW7'!C$5,'SW7'!D$5,_xll.RiskTruncateP(0.05,0.95),_xll.RiskName("Serum Part"))} -> #NAME?
A7: =A6+1 -> 4 | B7: {=B6+_xll.RiskNormal(0.5584 + 2*0.001787*A7 -3*0.00000155*A7^2 - 4*0.00000000133*A7^3,0.35*(0.5584 + 2*0.001787*A7 -3*0.00000155*A7^2 - 4*0.00000000133*A7^3),_xll.RiskTruncateP(0.05,0.95),_xll.RiskName("BW Gain"),_xll.RiskUnits("kg"))} -> #NAME? | C7: {=_xll.RiskNormal(50,50*0.3941,_xll.RiskTruncateP(0.05,0.95),_xll.RiskName("Diet 1 Feed"),_xll.RiskUnits("ng/kg dry"))} -> #NAME? | D7: {=_xll.RiskNormal(550,550*0.282,_xll.RiskTruncateP(0.05,0.95),_xll.RiskName("Diet 1 Soil"),_xll.RiskUnits("ng/kg dry"))} -> #NAME? | E7: 1.3 | F7: {=_xll.RiskNormal((-0.0001*A7^2+0.0196*A7+11.697),(-0.0001*A7^2+0.0196*A7+11.697)*0.062,_xll.RiskTruncateP(0.05,0.95),_xll.RiskName("DMI Cow"),_xll.RiskUnits("kg"))} -> #NAME? | G7: {=_xll.RiskNormal(F7*0.0243,F7*0.005,_xll.RiskTruncateP(0.05,0.95),_xll.RiskName("Soil Intake Cow"),_xll.RiskUnits("kg"))} -> #NAME? | H7: {=_xll.RiskNormal('SW7'!C$12,'SW7'!D$12,_xll.RiskTruncateP(0.05,0.95),_xll.RiskName("Water Intake Cow"),_xll.RiskUnits("L"))} -> #NAME? | I7: =F7*C7+G7*D7+H7*E7 -> #NAME? | J7: =I7*0.0213 -> #NAME? | K7: {=_xll.RiskNormal(-0.0000000257*A7^4+0.0000163*A7^3-0.003686*A7^2+0.3024*A7+1.445,(-0.0000000257*A7^4+0.0000163*A7^3-0.003686*A7^2+0.3024*A7+1.445)*0.355,_xll.RiskTruncateP(0.05,0.95),_xll.RiskName("Milk Intake"),_xll.RiskUnits("kg"))} -> #NAME? | M7: {=_xll.RiskNormal(0.0243*L7,0.005*L7,_xll.RiskTruncateP(0.05,0.95),_xll.RiskName("Soil Intake"),_xll.RiskUnits("kg"))} -> #NAME? | N7: =4*L7 -> 0 | O7: =J7*K7 -> #NAME? | P7: =C7*L7 -> #NAME? | Q7: =D7*M7 -> #NAME? | R7: =E7*N7 -> 0 | S7: =SUM(O7:R7) -> #NAME? | T7: {=U6-(U6*(0.5^(1/_xll.RiskNormal('SW7'!C$2,'SW7'!D$2,_xll.RiskTruncateP(0.05,0.95),_xll.RiskName("Halflife"),_xll.RiskUnits("d")))))} -> #NAME? | U7: =U6+S6-T6 -> #NAME? | V7: {=(U7*_xll.RiskNormal('SW7'!C$3,'SW7'!D$3,_xll.RiskTruncateP(0.05,0.95),_xll.RiskName("PFAS MUSCLE FRAC"))/(B7*_xll.RiskNormal('SW7'!C$4,'SW7'!E$4,_xll.RiskTruncateP(0.05,0.95),_xll.RiskName("MUSCLE BW FRAC"))))/1000} -> #NAME? | W7: {=V7/_xll.RiskNormal('SW7'!C$5,'SW7'!D$5,_xll.RiskTruncateP(0.05,0.95),_xll.RiskName("Serum Part"))} -> #NAME?
